
ERROR 2025-03-28 01:18:43,317 views 데이터베이스 저장 중 오류 발생: 장비 정보 생성 중 오류 발생: Cannot add "<ItemEquipment: 하이네스 어새신보닛>": the value for field "itemequipment" is None
ERROR 2025-03-28 01:20:04,022 views 데이터베이스 저장 중 오류 발생: 장비 정보 생성 중 오류 발생: Cannot add "<ItemEquipment: 하이네스 어새신보닛>": the value for field "itemequipment" is None
ERROR 2025-03-28 01:21:11,018 views 데이터베이스 저장 중 오류 발생: 장비 정보 생성 중 오류 발생: Cannot add "<ItemEquipment: 하이네스 어새신보닛>": the value for field "itemequipment" is None
ERROR 2025-03-28 01:23:11,910 views 데이터베이스 저장 중 오류 발생: 장비 정보 생성 중 오류 발생: Cannot add "<ItemEquipment: 하이네스 어새신보닛>": the value for field "itemequipment" is None
ERROR 2025-03-28 01:39:40,756 views 데이터베이스 저장 중 오류 발생: 장비 정보 생성 중 오류 발생: get() returned more than one ItemEquipment -- it returned more than 20!
ERROR 2025-03-28 01:39:48,752 views 데이터베이스 저장 중 오류 발생: 장비 정보 생성 중 오류 발생: get() returned more than one ItemEquipment -- it returned more than 20!
ERROR 2025-03-28 01:39:53,214 views 데이터베이스 저장 중 오류 발생: 장비 정보 생성 중 오류 발생: get() returned more than one ItemEquipment -- it returned more than 20!
ERROR 2025-03-28 01:41:24,709 views 데이터베이스 저장 중 오류 발생: 장비 정보 생성 중 오류 발생: get() returned more than one ItemEquipment -- it returned more than 20!
ERROR 2025-03-28 01:41:41,280 views 데이터베이스 저장 중 오류 발생: 장비 정보 생성 중 오류 발생: get() returned more than one ItemEquipment -- it returned more than 20!
ERROR 2025-03-28 01:41:43,422 views 데이터베이스 저장 중 오류 발생: 장비 정보 생성 중 오류 발생: get() returned more than one ItemEquipment -- it returned more than 20!
ERROR 2025-03-28 01:41:45,830 views 데이터베이스 저장 중 오류 발생: 장비 정보 생성 중 오류 발생: get() returned more than one ItemEquipment -- it returned more than 20!
ERROR 2025-03-28 01:41:52,706 views 데이터베이스 저장 중 오류 발생: 장비 정보 생성 중 오류 발생: get() returned more than one ItemEquipment -- it returned more than 20!
ERROR 2025-03-28 01:42:09,475 views 데이터베이스 저장 중 오류 발생: 장비 정보 생성 중 오류 발생: get() returned more than one ItemEquipment -- it returned more than 20!
ERROR 2025-03-28 01:42:13,587 views 데이터베이스 저장 중 오류 발생: 장비 정보 생성 중 오류 발생: get() returned more than one ItemEquipment -- it returned more than 20!
ERROR 2025-03-28 01:42:33,490 views 데이터베이스 저장 중 오류 발생: 장비 정보 생성 중 오류 발생: get() returned more than one ItemEquipment -- it returned more than 20!
ERROR 2025-03-28 01:43:03,282 views 데이터베이스 저장 중 오류 발생: 장비 정보 생성 중 오류 발생: get() returned more than one ItemEquipment -- it returned more than 20!
ERROR 2025-03-28 01:43:18,349 views 데이터베이스 저장 중 오류 발생: 장비 정보 생성 중 오류 발생: get() returned more than one ItemEquipment -- it returned more than 20!
ERROR 2025-03-28 01:43:32,315 views 데이터베이스 저장 중 오류 발생: 장비 정보 생성 중 오류 발생: get() returned more than one ItemEquipment -- it returned more than 20!
ERROR 2025-03-28 01:44:53,605 views 데이터베이스 저장 중 오류 발생: 장비 정보 생성 중 오류 발생: get() returned more than one ItemEquipment -- it returned more than 20!
ERROR 2025-04-06 22:06:48,387 log Internal Server Error: /characters/id/
Traceback (most recent call last):
  File "c:\Users\Hong\workspace\maplestorage\maplestorage_backend\.venv\lib\site-packages\redis\connection.py", line 357, in connect
    sock = self.retry.call_with_retry(
  File "c:\Users\Hong\workspace\maplestorage\maplestorage_backend\.venv\lib\site-packages\redis\retry.py", line 62, in call_with_retry
    return do()
  File "c:\Users\Hong\workspace\maplestorage\maplestorage_backend\.venv\lib\site-packages\redis\connection.py", line 358, in <lambda>
    lambda: self._connect(), lambda error: self.disconnect(error)
  File "c:\Users\Hong\workspace\maplestorage\maplestorage_backend\.venv\lib\site-packages\redis\connection.py", line 730, in _connect
    raise err
  File "c:\Users\Hong\workspace\maplestorage\maplestorage_backend\.venv\lib\site-packages\redis\connection.py", line 718, in _connect
    sock.connect(socket_address)
ConnectionRefusedError: [WinError 10061] 대상 컴퓨터에서 연결을 거부했으므로 연결하지 못했습니다

During handling of the above exception, another exception occurred:

Traceback (most recent call last):
  File "c:\Users\Hong\workspace\maplestorage\maplestorage_backend\.venv\lib\site-packages\django\core\handlers\exception.py", line 55, in inner
    response = get_response(request)
  File "c:\Users\Hong\workspace\maplestorage\maplestorage_backend\.venv\lib\site-packages\django\core\handlers\base.py", line 197, in _get_response
    response = wrapped_callback(request, *callback_args, **callback_kwargs)
  File "c:\Users\Hong\workspace\maplestorage\maplestorage_backend\.venv\lib\site-packages\django\views\decorators\csrf.py", line 65, in _view_wrapper
    return view_func(request, *args, **kwargs)
  File "c:\Users\Hong\workspace\maplestorage\maplestorage_backend\.venv\lib\site-packages\django\views\generic\base.py", line 104, in view
    return self.dispatch(request, *args, **kwargs)
  File "c:\Users\Hong\workspace\maplestorage\maplestorage_backend\.venv\lib\site-packages\rest_framework\views.py", line 509, in dispatch
    response = self.handle_exception(exc)
  File "C:\Users\Hong\workspace\maplestorage\maplestorage_backend\characters\mixins.py", line 128, in handle_exception
    return super().handle_exception(exc)
  File "c:\Users\Hong\workspace\maplestorage\maplestorage_backend\.venv\lib\site-packages\rest_framework\views.py", line 469, in handle_exception
    self.raise_uncaught_exception(exc)
  File "c:\Users\Hong\workspace\maplestorage\maplestorage_backend\.venv\lib\site-packages\rest_framework\views.py", line 480, in raise_uncaught_exception
    raise exc
  File "c:\Users\Hong\workspace\maplestorage\maplestorage_backend\.venv\lib\site-packages\rest_framework\views.py", line 506, in dispatch
    response = handler(request, *args, **kwargs)
  File "C:\Users\Hong\workspace\maplestorage\maplestorage_backend\characters\views.py", line 255, in get
    return self.handle_exception(e)
  File "C:\Users\Hong\workspace\maplestorage\maplestorage_backend\characters\mixins.py", line 128, in handle_exception
    return super().handle_exception(exc)
  File "c:\Users\Hong\workspace\maplestorage\maplestorage_backend\.venv\lib\site-packages\rest_framework\views.py", line 469, in handle_exception
    self.raise_uncaught_exception(exc)
  File "c:\Users\Hong\workspace\maplestorage\maplestorage_backend\.venv\lib\site-packages\rest_framework\views.py", line 480, in raise_uncaught_exception
    raise exc
  File "C:\Users\Hong\workspace\maplestorage\maplestorage_backend\characters\views.py", line 250, in get
    data = self._fetch_and_process_data(request)
  File "C:\Users\Hong\workspace\maplestorage\maplestorage_backend\characters\views.py", line 205, in _fetch_and_process_data
    data = self.get_api_data(
  File "C:\Users\Hong\workspace\maplestorage\maplestorage_backend\util\rate_limiter.py", line 48, in wrapper
    check_rate_limit(max_calls)
  File "C:\Users\Hong\workspace\maplestorage\maplestorage_backend\util\rate_limiter.py", line 19, in check_rate_limit
    current_count = pipe.incr(key).expire(key, 2).execute()[0]
  File "c:\Users\Hong\workspace\maplestorage\maplestorage_backend\.venv\lib\site-packages\redis\client.py", line 1524, in execute
    conn = self.connection_pool.get_connection("MULTI", self.shard_hint)
  File "c:\Users\Hong\workspace\maplestorage\maplestorage_backend\.venv\lib\site-packages\redis\connection.py", line 1422, in get_connection
    connection.connect()
  File "c:\Users\Hong\workspace\maplestorage\maplestorage_backend\.venv\lib\site-packages\redis\connection.py", line 363, in connect
    raise ConnectionError(self._error_message(e))
redis.exceptions.ConnectionError: Error 10061 connecting to localhost:6379. 대상 컴퓨터에서 연결을 거부했으므로 연결하지 못했습니다.
ERROR 2025-04-07 01:12:49,169 views 데이터베이스 저장 중 오류 발생: 인기도 정보 생성 중 오류 발생: 'NoneType' object has no attribute 'astimezone'
ERROR 2025-04-07 01:12:49,346 views 데이터베이스 저장 중 오류 발생: V매트릭스 정보 생성 중 오류 발생: 'NoneType' object has no attribute 'astimezone'
ERROR 2025-04-07 01:12:49,465 views 데이터베이스 저장 중 오류 발생: 장비 정보 생성 중 오류 발생: 'NoneType' object has no attribute 'astimezone'
ERROR 2025-04-07 01:13:37,483 views 데이터베이스 저장 중 오류 발생: V매트릭스 정보 생성 중 오류 발생: 'NoneType' object has no attribute 'astimezone'
ERROR 2025-04-07 01:13:37,588 views 데이터베이스 저장 중 오류 발생: 인기도 정보 생성 중 오류 발생: 'NoneType' object has no attribute 'astimezone'
ERROR 2025-04-07 01:13:38,405 views 데이터베이스 저장 중 오류 발생: 장비 정보 생성 중 오류 발생: 'NoneType' object has no attribute 'astimezone'
ERROR 2025-04-07 01:13:52,650 views 데이터베이스 저장 중 오류 발생: V매트릭스 정보 생성 중 오류 발생: 'NoneType' object has no attribute 'astimezone'
ERROR 2025-04-07 01:13:52,959 views 데이터베이스 저장 중 오류 발생: 인기도 정보 생성 중 오류 발생: 'NoneType' object has no attribute 'astimezone'
ERROR 2025-04-07 01:13:53,079 views 데이터베이스 저장 중 오류 발생: 장비 정보 생성 중 오류 발생: 'NoneType' object has no attribute 'astimezone'
ERROR 2025-04-07 01:17:10,785 views 데이터베이스 저장 중 오류 발생: 인기도 정보 생성 중 오류 발생: 'NoneType' object has no attribute 'astimezone'
ERROR 2025-04-07 01:17:11,462 views 데이터베이스 저장 중 오류 발생: V매트릭스 정보 생성 중 오류 발생: 'NoneType' object has no attribute 'astimezone'
ERROR 2025-04-07 01:17:11,813 views 데이터베이스 저장 중 오류 발생: 장비 정보 생성 중 오류 발생: 'NoneType' object has no attribute 'astimezone'
ERROR 2025-04-07 01:17:11,971 views 데이터베이스 저장 중 오류 발생: 인기도 정보 생성 중 오류 발생: 'NoneType' object has no attribute 'astimezone'
ERROR 2025-04-07 01:17:12,131 views 데이터베이스 저장 중 오류 발생: V매트릭스 정보 생성 중 오류 발생: 'NoneType' object has no attribute 'astimezone'
ERROR 2025-04-07 01:17:13,527 views 데이터베이스 저장 중 오류 발생: 장비 정보 생성 중 오류 발생: 'NoneType' object has no attribute 'astimezone'
ERROR 2025-04-07 01:17:51,405 views 데이터베이스 저장 중 오류 발생: V매트릭스 정보 생성 중 오류 발생: 'NoneType' object has no attribute 'astimezone'
ERROR 2025-04-07 01:19:59,055 views 데이터베이스 저장 중 오류 발생: 인기도 정보 생성 중 오류 발생: 'NoneType' object has no attribute 'astimezone'
ERROR 2025-04-07 01:21:14,048 views 데이터베이스 저장 중 오류 발생: 인기도 정보 생성 중 오류 발생: 'NoneType' object has no attribute 'astimezone'
ERROR 2025-04-07 01:21:14,050 views 데이터베이스 저장 중 오류 발생: V매트릭스 정보 생성 중 오류 발생: 'NoneType' object has no attribute 'astimezone'
ERROR 2025-04-07 01:21:14,298 views 데이터베이스 저장 중 오류 발생: 장비 정보 생성 중 오류 발생: 'NoneType' object has no attribute 'astimezone'
ERROR 2025-04-07 01:22:03,373 views 데이터베이스 저장 중 오류 발생: 인기도 정보 생성 중 오류 발생: 'NoneType' object has no attribute 'astimezone'
ERROR 2025-04-07 01:22:03,484 views 데이터베이스 저장 중 오류 발생: V매트릭스 정보 생성 중 오류 발생: 'NoneType' object has no attribute 'astimezone'
ERROR 2025-04-07 01:22:03,687 views 데이터베이스 저장 중 오류 발생: 장비 정보 생성 중 오류 발생: 'NoneType' object has no attribute 'astimezone'
ERROR 2025-04-07 01:22:16,901 views 데이터베이스 저장 중 오류 발생: V매트릭스 정보 생성 중 오류 발생: 'NoneType' object has no attribute 'astimezone'
ERROR 2025-04-07 01:22:16,968 views 데이터베이스 저장 중 오류 발생: 인기도 정보 생성 중 오류 발생: 'NoneType' object has no attribute 'astimezone'
ERROR 2025-04-07 01:22:18,421 views 데이터베이스 저장 중 오류 발생: 장비 정보 생성 중 오류 발생: 'NoneType' object has no attribute 'astimezone'
ERROR 2025-04-07 01:25:36,442 views 데이터베이스 저장 중 오류 발생: V매트릭스 정보 생성 중 오류 발생: 'NoneType' object has no attribute 'astimezone'
ERROR 2025-04-07 01:25:36,566 views 데이터베이스 저장 중 오류 발생: 인기도 정보 생성 중 오류 발생: 'NoneType' object has no attribute 'astimezone'
ERROR 2025-04-07 01:25:37,223 views 데이터베이스 저장 중 오류 발생: 장비 정보 생성 중 오류 발생: 'NoneType' object has no attribute 'astimezone'
ERROR 2025-04-07 01:29:08,291 views 전체 데이터 조회 중 오류 발생: local variable 'json' referenced before assignment
ERROR 2025-04-07 01:29:08,294 views Traceback (most recent call last):
  File "C:\Users\Hong\workspace\maplestorage\maplestorage_backend\characters\views.py", line 587, in get
    return Response({'data': json.loads(cached_data)})
UnboundLocalError: local variable 'json' referenced before assignment

During handling of the above exception, another exception occurred:

Traceback (most recent call last):
  File "C:\Users\Hong\workspace\maplestorage\maplestorage_backend\characters\views.py", line 588, in get
    except json.JSONDecodeError:
UnboundLocalError: local variable 'json' referenced before assignment

ERROR 2025-04-07 01:29:08,295 log Internal Server Error: /characters/all/
ERROR 2025-04-07 01:29:21,515 views 전체 데이터 조회 중 오류 발생: local variable 'json' referenced before assignment
ERROR 2025-04-07 01:29:21,517 views Traceback (most recent call last):
  File "C:\Users\Hong\workspace\maplestorage\maplestorage_backend\characters\views.py", line 587, in get
    return Response({'data': json.loads(cached_data)})
UnboundLocalError: local variable 'json' referenced before assignment

During handling of the above exception, another exception occurred:

Traceback (most recent call last):
  File "C:\Users\Hong\workspace\maplestorage\maplestorage_backend\characters\views.py", line 588, in get
    except json.JSONDecodeError:
UnboundLocalError: local variable 'json' referenced before assignment

ERROR 2025-04-07 01:29:21,518 log Internal Server Error: /characters/all/
ERROR 2025-04-07 01:30:53,774 views 전체 데이터 조회 중 오류 발생: 400 Client Error: Bad Request for url: https://open.api.nexon.com/maplestory/v1/id?character_name=%EC%8B%9D%EB%86%88%EB%B3%B4%EB%A7%88%E3%85%A3
ERROR 2025-04-07 01:30:53,787 views Traceback (most recent call last):
  File "C:\Users\Hong\workspace\maplestorage\maplestorage_backend\characters\views.py", line 552, in get
    ocid_data = CharacterIdView()._fetch_and_process_data(request)
  File "C:\Users\Hong\workspace\maplestorage\maplestorage_backend\characters\views.py", line 207, in _fetch_and_process_data
    data = self.get_api_data(
  File "C:\Users\Hong\workspace\maplestorage\maplestorage_backend\util\rate_limiter.py", line 49, in wrapper
    return func(*args, **kwargs)
  File "C:\Users\Hong\workspace\maplestorage\maplestorage_backend\characters\mixins.py", line 51, in get_api_data
    response.raise_for_status()
  File "c:\Users\Hong\workspace\maplestorage\maplestorage_backend\.venv\lib\site-packages\requests\models.py", line 1024, in raise_for_status
    raise HTTPError(http_error_msg, response=self)
requests.exceptions.HTTPError: 400 Client Error: Bad Request for url: https://open.api.nexon.com/maplestory/v1/id?character_name=%EC%8B%9D%EB%86%88%EB%B3%B4%EB%A7%88%E3%85%A3

ERROR 2025-04-07 01:30:53,789 log Internal Server Error: /characters/all/
ERROR 2025-04-07 01:31:08,940 views 데이터베이스 저장 중 오류 발생: 인기도 정보 생성 중 오류 발생: 'NoneType' object has no attribute 'astimezone'
ERROR 2025-04-07 01:31:09,007 views 데이터베이스 저장 중 오류 발생: V매트릭스 정보 생성 중 오류 발생: 'NoneType' object has no attribute 'astimezone'
ERROR 2025-04-07 01:31:09,395 views 데이터베이스 저장 중 오류 발생: 장비 정보 생성 중 오류 발생: 'NoneType' object has no attribute 'astimezone'
ERROR 2025-04-07 01:38:23,834 views 데이터베이스 저장 중 오류 발생: 인기도 정보 생성 중 오류 발생: 'NoneType' object has no attribute 'astimezone'
ERROR 2025-04-07 01:38:23,966 views 데이터베이스 저장 중 오류 발생: V매트릭스 정보 생성 중 오류 발생: 'NoneType' object has no attribute 'astimezone'
ERROR 2025-04-07 01:38:24,003 views 데이터베이스 저장 중 오류 발생: 장비 정보 생성 중 오류 발생: 'NoneType' object has no attribute 'astimezone'
ERROR 2025-04-07 01:40:27,540 views 데이터베이스 저장 중 오류 발생: 인기도 정보 생성 중 오류 발생: 'NoneType' object has no attribute 'astimezone'
ERROR 2025-04-07 01:40:27,946 views 데이터베이스 저장 중 오류 발생: 장비 정보 생성 중 오류 발생: 'NoneType' object has no attribute 'astimezone'
ERROR 2025-04-07 01:40:28,126 views 데이터베이스 저장 중 오류 발생: V매트릭스 정보 생성 중 오류 발생: 'NoneType' object has no attribute 'astimezone'
ERROR 2025-04-07 01:40:35,944 views 데이터베이스 저장 중 오류 발생: 인기도 정보 생성 중 오류 발생: 'NoneType' object has no attribute 'astimezone'
ERROR 2025-04-07 01:40:36,829 views 데이터베이스 저장 중 오류 발생: V매트릭스 정보 생성 중 오류 발생: 'NoneType' object has no attribute 'astimezone'
ERROR 2025-04-07 01:40:36,965 views 데이터베이스 저장 중 오류 발생: 장비 정보 생성 중 오류 발생: 'NoneType' object has no attribute 'astimezone'
ERROR 2025-04-07 01:41:07,171 views 데이터베이스 저장 중 오류 발생: 인기도 정보 생성 중 오류 발생: 'NoneType' object has no attribute 'astimezone'
ERROR 2025-04-07 01:41:08,367 views 데이터베이스 저장 중 오류 발생: V매트릭스 정보 생성 중 오류 발생: 'NoneType' object has no attribute 'astimezone'
ERROR 2025-04-07 01:41:08,595 views 데이터베이스 저장 중 오류 발생: 장비 정보 생성 중 오류 발생: 'NoneType' object has no attribute 'astimezone'
ERROR 2025-04-07 01:42:29,289 views 데이터베이스 저장 중 오류 발생: V매트릭스 정보 생성 중 오류 발생: 'NoneType' object has no attribute 'astimezone'
ERROR 2025-04-07 01:42:29,887 views 데이터베이스 저장 중 오류 발생: 인기도 정보 생성 중 오류 발생: 'NoneType' object has no attribute 'astimezone'
ERROR 2025-04-07 01:44:55,119 views 데이터베이스 저장 중 오류 발생: 장비 정보 생성 중 오류 발생: 'NoneType' object has no attribute 'astimezone'
ERROR 2025-04-07 01:44:55,366 views API 호출/처리 중 예외 발생 (https://open.api.nexon.com/maplestory/v1/character/skill): cannot schedule new futures after interpreter shutdown
ERROR 2025-04-07 01:44:55,393 views Traceback (most recent call last):
  File "C:\Users\Hong\workspace\maplestorage\maplestorage_backend\characters\views.py", line 697, in fetch_with_semaphore
    async with session.get(url, params=params, headers=headers) as response:
  File "c:\Users\Hong\workspace\maplestorage\maplestorage_backend\.venv\lib\site-packages\aiohttp\client.py", line 1425, in __aenter__
    self._resp: _RetType = await self._coro
  File "c:\Users\Hong\workspace\maplestorage\maplestorage_backend\.venv\lib\site-packages\aiohttp\client.py", line 703, in _request
    conn = await self._connector.connect(
  File "c:\Users\Hong\workspace\maplestorage\maplestorage_backend\.venv\lib\site-packages\aiohttp\connector.py", line 548, in connect
    proto = await self._create_connection(req, traces, timeout)
  File "c:\Users\Hong\workspace\maplestorage\maplestorage_backend\.venv\lib\site-packages\aiohttp\connector.py", line 1056, in _create_connection
    _, proto = await self._create_direct_connection(req, traces, timeout)
  File "c:\Users\Hong\workspace\maplestorage\maplestorage_backend\.venv\lib\site-packages\aiohttp\connector.py", line 1351, in _create_direct_connection
    hosts = await self._resolve_host(host, port, traces=traces)
  File "c:\Users\Hong\workspace\maplestorage\maplestorage_backend\.venv\lib\site-packages\aiohttp\connector.py", line 970, in _resolve_host
    await future
  File "c:\Users\Hong\workspace\maplestorage\maplestorage_backend\.venv\lib\site-packages\aiohttp\connector.py", line 1026, in _resolve_host_with_throttle
    addrs = await self._resolver.resolve(host, port, family=self._family)
  File "c:\Users\Hong\workspace\maplestorage\maplestorage_backend\.venv\lib\site-packages\aiohttp\resolver.py", line 39, in resolve
    infos = await self._loop.getaddrinfo(
  File "C:\Users\Hong\AppData\Local\Programs\Python\Python310\lib\asyncio\base_events.py", line 860, in getaddrinfo
    return await self.run_in_executor(
  File "C:\Users\Hong\AppData\Local\Programs\Python\Python310\lib\asyncio\base_events.py", line 818, in run_in_executor
    executor.submit(func, *args), loop=self)
  File "C:\Users\Hong\AppData\Local\Programs\Python\Python310\lib\concurrent\futures\thread.py", line 169, in submit
    raise RuntimeError('cannot schedule new futures after '
RuntimeError: cannot schedule new futures after interpreter shutdown

ERROR 2025-04-07 01:44:55,394 views API 호출/처리 중 예외 발생 (https://open.api.nexon.com/maplestory/v1/character/vmatrix): cannot schedule new futures after interpreter shutdown
ERROR 2025-04-07 01:44:55,397 views Traceback (most recent call last):
  File "C:\Users\Hong\workspace\maplestorage\maplestorage_backend\characters\views.py", line 697, in fetch_with_semaphore
    async with session.get(url, params=params, headers=headers) as response:
  File "c:\Users\Hong\workspace\maplestorage\maplestorage_backend\.venv\lib\site-packages\aiohttp\client.py", line 1425, in __aenter__
    self._resp: _RetType = await self._coro
  File "c:\Users\Hong\workspace\maplestorage\maplestorage_backend\.venv\lib\site-packages\aiohttp\client.py", line 703, in _request
    conn = await self._connector.connect(
  File "c:\Users\Hong\workspace\maplestorage\maplestorage_backend\.venv\lib\site-packages\aiohttp\connector.py", line 548, in connect
    proto = await self._create_connection(req, traces, timeout)
  File "c:\Users\Hong\workspace\maplestorage\maplestorage_backend\.venv\lib\site-packages\aiohttp\connector.py", line 1056, in _create_connection
    _, proto = await self._create_direct_connection(req, traces, timeout)
  File "c:\Users\Hong\workspace\maplestorage\maplestorage_backend\.venv\lib\site-packages\aiohttp\connector.py", line 1351, in _create_direct_connection
    hosts = await self._resolve_host(host, port, traces=traces)
  File "c:\Users\Hong\workspace\maplestorage\maplestorage_backend\.venv\lib\site-packages\aiohttp\connector.py", line 970, in _resolve_host
    await future
  File "c:\Users\Hong\workspace\maplestorage\maplestorage_backend\.venv\lib\site-packages\aiohttp\connector.py", line 1026, in _resolve_host_with_throttle
    addrs = await self._resolver.resolve(host, port, family=self._family)
  File "c:\Users\Hong\workspace\maplestorage\maplestorage_backend\.venv\lib\site-packages\aiohttp\resolver.py", line 39, in resolve
    infos = await self._loop.getaddrinfo(
  File "C:\Users\Hong\AppData\Local\Programs\Python\Python310\lib\asyncio\base_events.py", line 860, in getaddrinfo
    return await self.run_in_executor(
  File "C:\Users\Hong\AppData\Local\Programs\Python\Python310\lib\asyncio\base_events.py", line 818, in run_in_executor
    executor.submit(func, *args), loop=self)
  File "C:\Users\Hong\AppData\Local\Programs\Python\Python310\lib\concurrent\futures\thread.py", line 169, in submit
    raise RuntimeError('cannot schedule new futures after '
RuntimeError: cannot schedule new futures after interpreter shutdown

ERROR 2025-04-07 01:44:55,399 views API 호출/처리 중 예외 발생 (https://open.api.nexon.com/maplestory/v1/character/android-equipment): cannot schedule new futures after interpreter shutdown
ERROR 2025-04-07 01:44:55,403 views Traceback (most recent call last):
  File "C:\Users\Hong\workspace\maplestorage\maplestorage_backend\characters\views.py", line 697, in fetch_with_semaphore
    async with session.get(url, params=params, headers=headers) as response:
  File "c:\Users\Hong\workspace\maplestorage\maplestorage_backend\.venv\lib\site-packages\aiohttp\client.py", line 1425, in __aenter__
    self._resp: _RetType = await self._coro
  File "c:\Users\Hong\workspace\maplestorage\maplestorage_backend\.venv\lib\site-packages\aiohttp\client.py", line 703, in _request
    conn = await self._connector.connect(
  File "c:\Users\Hong\workspace\maplestorage\maplestorage_backend\.venv\lib\site-packages\aiohttp\connector.py", line 548, in connect
    proto = await self._create_connection(req, traces, timeout)
  File "c:\Users\Hong\workspace\maplestorage\maplestorage_backend\.venv\lib\site-packages\aiohttp\connector.py", line 1056, in _create_connection
    _, proto = await self._create_direct_connection(req, traces, timeout)
  File "c:\Users\Hong\workspace\maplestorage\maplestorage_backend\.venv\lib\site-packages\aiohttp\connector.py", line 1351, in _create_direct_connection
    hosts = await self._resolve_host(host, port, traces=traces)
  File "c:\Users\Hong\workspace\maplestorage\maplestorage_backend\.venv\lib\site-packages\aiohttp\connector.py", line 970, in _resolve_host
    await future
  File "c:\Users\Hong\workspace\maplestorage\maplestorage_backend\.venv\lib\site-packages\aiohttp\connector.py", line 1026, in _resolve_host_with_throttle
    addrs = await self._resolver.resolve(host, port, family=self._family)
  File "c:\Users\Hong\workspace\maplestorage\maplestorage_backend\.venv\lib\site-packages\aiohttp\resolver.py", line 39, in resolve
    infos = await self._loop.getaddrinfo(
  File "C:\Users\Hong\AppData\Local\Programs\Python\Python310\lib\asyncio\base_events.py", line 860, in getaddrinfo
    return await self.run_in_executor(
  File "C:\Users\Hong\AppData\Local\Programs\Python\Python310\lib\asyncio\base_events.py", line 818, in run_in_executor
    executor.submit(func, *args), loop=self)
  File "C:\Users\Hong\AppData\Local\Programs\Python\Python310\lib\concurrent\futures\thread.py", line 169, in submit
    raise RuntimeError('cannot schedule new futures after '
RuntimeError: cannot schedule new futures after interpreter shutdown

ERROR 2025-04-07 01:44:55,404 views API 호출/처리 중 예외 발생 (https://open.api.nexon.com/maplestory/v1/character/stat): cannot schedule new futures after interpreter shutdown
ERROR 2025-04-07 01:44:55,406 views Traceback (most recent call last):
  File "C:\Users\Hong\workspace\maplestorage\maplestorage_backend\characters\views.py", line 697, in fetch_with_semaphore
    async with session.get(url, params=params, headers=headers) as response:
  File "c:\Users\Hong\workspace\maplestorage\maplestorage_backend\.venv\lib\site-packages\aiohttp\client.py", line 1425, in __aenter__
    self._resp: _RetType = await self._coro
  File "c:\Users\Hong\workspace\maplestorage\maplestorage_backend\.venv\lib\site-packages\aiohttp\client.py", line 703, in _request
    conn = await self._connector.connect(
  File "c:\Users\Hong\workspace\maplestorage\maplestorage_backend\.venv\lib\site-packages\aiohttp\connector.py", line 548, in connect
    proto = await self._create_connection(req, traces, timeout)
  File "c:\Users\Hong\workspace\maplestorage\maplestorage_backend\.venv\lib\site-packages\aiohttp\connector.py", line 1056, in _create_connection
    _, proto = await self._create_direct_connection(req, traces, timeout)
  File "c:\Users\Hong\workspace\maplestorage\maplestorage_backend\.venv\lib\site-packages\aiohttp\connector.py", line 1351, in _create_direct_connection
    hosts = await self._resolve_host(host, port, traces=traces)
  File "c:\Users\Hong\workspace\maplestorage\maplestorage_backend\.venv\lib\site-packages\aiohttp\connector.py", line 970, in _resolve_host
    await future
  File "c:\Users\Hong\workspace\maplestorage\maplestorage_backend\.venv\lib\site-packages\aiohttp\connector.py", line 1026, in _resolve_host_with_throttle
    addrs = await self._resolver.resolve(host, port, family=self._family)
  File "c:\Users\Hong\workspace\maplestorage\maplestorage_backend\.venv\lib\site-packages\aiohttp\resolver.py", line 39, in resolve
    infos = await self._loop.getaddrinfo(
  File "C:\Users\Hong\AppData\Local\Programs\Python\Python310\lib\asyncio\base_events.py", line 860, in getaddrinfo
    return await self.run_in_executor(
  File "C:\Users\Hong\AppData\Local\Programs\Python\Python310\lib\asyncio\base_events.py", line 818, in run_in_executor
    executor.submit(func, *args), loop=self)
  File "C:\Users\Hong\AppData\Local\Programs\Python\Python310\lib\concurrent\futures\thread.py", line 169, in submit
    raise RuntimeError('cannot schedule new futures after '
RuntimeError: cannot schedule new futures after interpreter shutdown

ERROR 2025-04-07 01:44:55,408 views API 호출/처리 중 예외 발생 (https://open.api.nexon.com/maplestory/v1/character/symbol-equipment): cannot schedule new futures after interpreter shutdown
ERROR 2025-04-07 01:44:55,411 views Traceback (most recent call last):
  File "C:\Users\Hong\workspace\maplestorage\maplestorage_backend\characters\views.py", line 697, in fetch_with_semaphore
    async with session.get(url, params=params, headers=headers) as response:
  File "c:\Users\Hong\workspace\maplestorage\maplestorage_backend\.venv\lib\site-packages\aiohttp\client.py", line 1425, in __aenter__
    self._resp: _RetType = await self._coro
  File "c:\Users\Hong\workspace\maplestorage\maplestorage_backend\.venv\lib\site-packages\aiohttp\client.py", line 703, in _request
    conn = await self._connector.connect(
  File "c:\Users\Hong\workspace\maplestorage\maplestorage_backend\.venv\lib\site-packages\aiohttp\connector.py", line 548, in connect
    proto = await self._create_connection(req, traces, timeout)
  File "c:\Users\Hong\workspace\maplestorage\maplestorage_backend\.venv\lib\site-packages\aiohttp\connector.py", line 1056, in _create_connection
    _, proto = await self._create_direct_connection(req, traces, timeout)
  File "c:\Users\Hong\workspace\maplestorage\maplestorage_backend\.venv\lib\site-packages\aiohttp\connector.py", line 1351, in _create_direct_connection
    hosts = await self._resolve_host(host, port, traces=traces)
  File "c:\Users\Hong\workspace\maplestorage\maplestorage_backend\.venv\lib\site-packages\aiohttp\connector.py", line 970, in _resolve_host
    await future
  File "c:\Users\Hong\workspace\maplestorage\maplestorage_backend\.venv\lib\site-packages\aiohttp\connector.py", line 1026, in _resolve_host_with_throttle
    addrs = await self._resolver.resolve(host, port, family=self._family)
  File "c:\Users\Hong\workspace\maplestorage\maplestorage_backend\.venv\lib\site-packages\aiohttp\resolver.py", line 39, in resolve
    infos = await self._loop.getaddrinfo(
  File "C:\Users\Hong\AppData\Local\Programs\Python\Python310\lib\asyncio\base_events.py", line 860, in getaddrinfo
    return await self.run_in_executor(
  File "C:\Users\Hong\AppData\Local\Programs\Python\Python310\lib\asyncio\base_events.py", line 818, in run_in_executor
    executor.submit(func, *args), loop=self)
  File "C:\Users\Hong\AppData\Local\Programs\Python\Python310\lib\concurrent\futures\thread.py", line 169, in submit
    raise RuntimeError('cannot schedule new futures after '
RuntimeError: cannot schedule new futures after interpreter shutdown

ERROR 2025-04-07 01:44:55,412 views API 호출/처리 중 예외 발생 (https://open.api.nexon.com/maplestory/v1/character/skill): cannot schedule new futures after interpreter shutdown
ERROR 2025-04-07 01:44:55,415 views Traceback (most recent call last):
  File "C:\Users\Hong\workspace\maplestorage\maplestorage_backend\characters\views.py", line 697, in fetch_with_semaphore
    async with session.get(url, params=params, headers=headers) as response:
  File "c:\Users\Hong\workspace\maplestorage\maplestorage_backend\.venv\lib\site-packages\aiohttp\client.py", line 1425, in __aenter__
    self._resp: _RetType = await self._coro
  File "c:\Users\Hong\workspace\maplestorage\maplestorage_backend\.venv\lib\site-packages\aiohttp\client.py", line 703, in _request
    conn = await self._connector.connect(
  File "c:\Users\Hong\workspace\maplestorage\maplestorage_backend\.venv\lib\site-packages\aiohttp\connector.py", line 548, in connect
    proto = await self._create_connection(req, traces, timeout)
  File "c:\Users\Hong\workspace\maplestorage\maplestorage_backend\.venv\lib\site-packages\aiohttp\connector.py", line 1056, in _create_connection
    _, proto = await self._create_direct_connection(req, traces, timeout)
  File "c:\Users\Hong\workspace\maplestorage\maplestorage_backend\.venv\lib\site-packages\aiohttp\connector.py", line 1351, in _create_direct_connection
    hosts = await self._resolve_host(host, port, traces=traces)
  File "c:\Users\Hong\workspace\maplestorage\maplestorage_backend\.venv\lib\site-packages\aiohttp\connector.py", line 970, in _resolve_host
    await future
  File "c:\Users\Hong\workspace\maplestorage\maplestorage_backend\.venv\lib\site-packages\aiohttp\connector.py", line 1026, in _resolve_host_with_throttle
    addrs = await self._resolver.resolve(host, port, family=self._family)
  File "c:\Users\Hong\workspace\maplestorage\maplestorage_backend\.venv\lib\site-packages\aiohttp\resolver.py", line 39, in resolve
    infos = await self._loop.getaddrinfo(
  File "C:\Users\Hong\AppData\Local\Programs\Python\Python310\lib\asyncio\base_events.py", line 860, in getaddrinfo
    return await self.run_in_executor(
  File "C:\Users\Hong\AppData\Local\Programs\Python\Python310\lib\asyncio\base_events.py", line 818, in run_in_executor
    executor.submit(func, *args), loop=self)
  File "C:\Users\Hong\AppData\Local\Programs\Python\Python310\lib\concurrent\futures\thread.py", line 169, in submit
    raise RuntimeError('cannot schedule new futures after '
RuntimeError: cannot schedule new futures after interpreter shutdown

ERROR 2025-04-07 01:44:55,416 views API 호출/처리 중 예외 발생 (https://open.api.nexon.com/maplestory/v1/character/dojang): cannot schedule new futures after interpreter shutdown
ERROR 2025-04-07 01:44:55,419 views Traceback (most recent call last):
  File "C:\Users\Hong\workspace\maplestorage\maplestorage_backend\characters\views.py", line 697, in fetch_with_semaphore
    async with session.get(url, params=params, headers=headers) as response:
  File "c:\Users\Hong\workspace\maplestorage\maplestorage_backend\.venv\lib\site-packages\aiohttp\client.py", line 1425, in __aenter__
    self._resp: _RetType = await self._coro
  File "c:\Users\Hong\workspace\maplestorage\maplestorage_backend\.venv\lib\site-packages\aiohttp\client.py", line 703, in _request
    conn = await self._connector.connect(
  File "c:\Users\Hong\workspace\maplestorage\maplestorage_backend\.venv\lib\site-packages\aiohttp\connector.py", line 548, in connect
    proto = await self._create_connection(req, traces, timeout)
  File "c:\Users\Hong\workspace\maplestorage\maplestorage_backend\.venv\lib\site-packages\aiohttp\connector.py", line 1056, in _create_connection
    _, proto = await self._create_direct_connection(req, traces, timeout)
  File "c:\Users\Hong\workspace\maplestorage\maplestorage_backend\.venv\lib\site-packages\aiohttp\connector.py", line 1351, in _create_direct_connection
    hosts = await self._resolve_host(host, port, traces=traces)
  File "c:\Users\Hong\workspace\maplestorage\maplestorage_backend\.venv\lib\site-packages\aiohttp\connector.py", line 970, in _resolve_host
    await future
  File "c:\Users\Hong\workspace\maplestorage\maplestorage_backend\.venv\lib\site-packages\aiohttp\connector.py", line 1026, in _resolve_host_with_throttle
    addrs = await self._resolver.resolve(host, port, family=self._family)
  File "c:\Users\Hong\workspace\maplestorage\maplestorage_backend\.venv\lib\site-packages\aiohttp\resolver.py", line 39, in resolve
    infos = await self._loop.getaddrinfo(
  File "C:\Users\Hong\AppData\Local\Programs\Python\Python310\lib\asyncio\base_events.py", line 860, in getaddrinfo
    return await self.run_in_executor(
  File "C:\Users\Hong\AppData\Local\Programs\Python\Python310\lib\asyncio\base_events.py", line 818, in run_in_executor
    executor.submit(func, *args), loop=self)
  File "C:\Users\Hong\AppData\Local\Programs\Python\Python310\lib\concurrent\futures\thread.py", line 169, in submit
    raise RuntimeError('cannot schedule new futures after '
RuntimeError: cannot schedule new futures after interpreter shutdown

ERROR 2025-04-07 01:44:55,420 views API 호출/처리 중 예외 발생 (https://open.api.nexon.com/maplestory/v1/character/pet-equipment): cannot schedule new futures after interpreter shutdown
ERROR 2025-04-07 01:44:55,422 views Traceback (most recent call last):
  File "C:\Users\Hong\workspace\maplestorage\maplestorage_backend\characters\views.py", line 697, in fetch_with_semaphore
    async with session.get(url, params=params, headers=headers) as response:
  File "c:\Users\Hong\workspace\maplestorage\maplestorage_backend\.venv\lib\site-packages\aiohttp\client.py", line 1425, in __aenter__
    self._resp: _RetType = await self._coro
  File "c:\Users\Hong\workspace\maplestorage\maplestorage_backend\.venv\lib\site-packages\aiohttp\client.py", line 703, in _request
    conn = await self._connector.connect(
  File "c:\Users\Hong\workspace\maplestorage\maplestorage_backend\.venv\lib\site-packages\aiohttp\connector.py", line 548, in connect
    proto = await self._create_connection(req, traces, timeout)
  File "c:\Users\Hong\workspace\maplestorage\maplestorage_backend\.venv\lib\site-packages\aiohttp\connector.py", line 1056, in _create_connection
    _, proto = await self._create_direct_connection(req, traces, timeout)
  File "c:\Users\Hong\workspace\maplestorage\maplestorage_backend\.venv\lib\site-packages\aiohttp\connector.py", line 1351, in _create_direct_connection
    hosts = await self._resolve_host(host, port, traces=traces)
  File "c:\Users\Hong\workspace\maplestorage\maplestorage_backend\.venv\lib\site-packages\aiohttp\connector.py", line 970, in _resolve_host
    await future
  File "c:\Users\Hong\workspace\maplestorage\maplestorage_backend\.venv\lib\site-packages\aiohttp\connector.py", line 1026, in _resolve_host_with_throttle
    addrs = await self._resolver.resolve(host, port, family=self._family)
  File "c:\Users\Hong\workspace\maplestorage\maplestorage_backend\.venv\lib\site-packages\aiohttp\resolver.py", line 39, in resolve
    infos = await self._loop.getaddrinfo(
  File "C:\Users\Hong\AppData\Local\Programs\Python\Python310\lib\asyncio\base_events.py", line 860, in getaddrinfo
    return await self.run_in_executor(
  File "C:\Users\Hong\AppData\Local\Programs\Python\Python310\lib\asyncio\base_events.py", line 818, in run_in_executor
    executor.submit(func, *args), loop=self)
  File "C:\Users\Hong\AppData\Local\Programs\Python\Python310\lib\concurrent\futures\thread.py", line 169, in submit
    raise RuntimeError('cannot schedule new futures after '
RuntimeError: cannot schedule new futures after interpreter shutdown

ERROR 2025-04-07 01:44:55,424 views API 호출/처리 중 예외 발생 (https://open.api.nexon.com/maplestory/v1/character/ability): cannot schedule new futures after interpreter shutdown
ERROR 2025-04-07 01:44:55,426 views Traceback (most recent call last):
  File "C:\Users\Hong\workspace\maplestorage\maplestorage_backend\characters\views.py", line 697, in fetch_with_semaphore
    async with session.get(url, params=params, headers=headers) as response:
  File "c:\Users\Hong\workspace\maplestorage\maplestorage_backend\.venv\lib\site-packages\aiohttp\client.py", line 1425, in __aenter__
    self._resp: _RetType = await self._coro
  File "c:\Users\Hong\workspace\maplestorage\maplestorage_backend\.venv\lib\site-packages\aiohttp\client.py", line 703, in _request
    conn = await self._connector.connect(
  File "c:\Users\Hong\workspace\maplestorage\maplestorage_backend\.venv\lib\site-packages\aiohttp\connector.py", line 548, in connect
    proto = await self._create_connection(req, traces, timeout)
  File "c:\Users\Hong\workspace\maplestorage\maplestorage_backend\.venv\lib\site-packages\aiohttp\connector.py", line 1056, in _create_connection
    _, proto = await self._create_direct_connection(req, traces, timeout)
  File "c:\Users\Hong\workspace\maplestorage\maplestorage_backend\.venv\lib\site-packages\aiohttp\connector.py", line 1351, in _create_direct_connection
    hosts = await self._resolve_host(host, port, traces=traces)
  File "c:\Users\Hong\workspace\maplestorage\maplestorage_backend\.venv\lib\site-packages\aiohttp\connector.py", line 970, in _resolve_host
    await future
  File "c:\Users\Hong\workspace\maplestorage\maplestorage_backend\.venv\lib\site-packages\aiohttp\connector.py", line 1026, in _resolve_host_with_throttle
    addrs = await self._resolver.resolve(host, port, family=self._family)
  File "c:\Users\Hong\workspace\maplestorage\maplestorage_backend\.venv\lib\site-packages\aiohttp\resolver.py", line 39, in resolve
    infos = await self._loop.getaddrinfo(
  File "C:\Users\Hong\AppData\Local\Programs\Python\Python310\lib\asyncio\base_events.py", line 860, in getaddrinfo
    return await self.run_in_executor(
  File "C:\Users\Hong\AppData\Local\Programs\Python\Python310\lib\asyncio\base_events.py", line 818, in run_in_executor
    executor.submit(func, *args), loop=self)
  File "C:\Users\Hong\AppData\Local\Programs\Python\Python310\lib\concurrent\futures\thread.py", line 169, in submit
    raise RuntimeError('cannot schedule new futures after '
RuntimeError: cannot schedule new futures after interpreter shutdown

ERROR 2025-04-07 01:44:55,427 views API 호출/처리 중 예외 발생 (https://open.api.nexon.com/maplestory/v1/character/link-skill): cannot schedule new futures after interpreter shutdown
ERROR 2025-04-07 01:44:55,429 views Traceback (most recent call last):
  File "C:\Users\Hong\workspace\maplestorage\maplestorage_backend\characters\views.py", line 697, in fetch_with_semaphore
    async with session.get(url, params=params, headers=headers) as response:
  File "c:\Users\Hong\workspace\maplestorage\maplestorage_backend\.venv\lib\site-packages\aiohttp\client.py", line 1425, in __aenter__
    self._resp: _RetType = await self._coro
  File "c:\Users\Hong\workspace\maplestorage\maplestorage_backend\.venv\lib\site-packages\aiohttp\client.py", line 703, in _request
    conn = await self._connector.connect(
  File "c:\Users\Hong\workspace\maplestorage\maplestorage_backend\.venv\lib\site-packages\aiohttp\connector.py", line 548, in connect
    proto = await self._create_connection(req, traces, timeout)
  File "c:\Users\Hong\workspace\maplestorage\maplestorage_backend\.venv\lib\site-packages\aiohttp\connector.py", line 1056, in _create_connection
    _, proto = await self._create_direct_connection(req, traces, timeout)
  File "c:\Users\Hong\workspace\maplestorage\maplestorage_backend\.venv\lib\site-packages\aiohttp\connector.py", line 1351, in _create_direct_connection
    hosts = await self._resolve_host(host, port, traces=traces)
  File "c:\Users\Hong\workspace\maplestorage\maplestorage_backend\.venv\lib\site-packages\aiohttp\connector.py", line 970, in _resolve_host
    await future
  File "c:\Users\Hong\workspace\maplestorage\maplestorage_backend\.venv\lib\site-packages\aiohttp\connector.py", line 1026, in _resolve_host_with_throttle
    addrs = await self._resolver.resolve(host, port, family=self._family)
  File "c:\Users\Hong\workspace\maplestorage\maplestorage_backend\.venv\lib\site-packages\aiohttp\resolver.py", line 39, in resolve
    infos = await self._loop.getaddrinfo(
  File "C:\Users\Hong\AppData\Local\Programs\Python\Python310\lib\asyncio\base_events.py", line 860, in getaddrinfo
    return await self.run_in_executor(
  File "C:\Users\Hong\AppData\Local\Programs\Python\Python310\lib\asyncio\base_events.py", line 818, in run_in_executor
    executor.submit(func, *args), loop=self)
  File "C:\Users\Hong\AppData\Local\Programs\Python\Python310\lib\concurrent\futures\thread.py", line 169, in submit
    raise RuntimeError('cannot schedule new futures after '
RuntimeError: cannot schedule new futures after interpreter shutdown

ERROR 2025-04-07 01:44:55,430 views API 호출/처리 중 예외 발생 (https://open.api.nexon.com/maplestory/v1/character/hexamatrix): cannot schedule new futures after interpreter shutdown
ERROR 2025-04-07 01:44:55,432 views Traceback (most recent call last):
  File "C:\Users\Hong\workspace\maplestorage\maplestorage_backend\characters\views.py", line 697, in fetch_with_semaphore
    async with session.get(url, params=params, headers=headers) as response:
  File "c:\Users\Hong\workspace\maplestorage\maplestorage_backend\.venv\lib\site-packages\aiohttp\client.py", line 1425, in __aenter__
    self._resp: _RetType = await self._coro
  File "c:\Users\Hong\workspace\maplestorage\maplestorage_backend\.venv\lib\site-packages\aiohttp\client.py", line 703, in _request
    conn = await self._connector.connect(
  File "c:\Users\Hong\workspace\maplestorage\maplestorage_backend\.venv\lib\site-packages\aiohttp\connector.py", line 548, in connect
    proto = await self._create_connection(req, traces, timeout)
  File "c:\Users\Hong\workspace\maplestorage\maplestorage_backend\.venv\lib\site-packages\aiohttp\connector.py", line 1056, in _create_connection
    _, proto = await self._create_direct_connection(req, traces, timeout)
  File "c:\Users\Hong\workspace\maplestorage\maplestorage_backend\.venv\lib\site-packages\aiohttp\connector.py", line 1351, in _create_direct_connection
    hosts = await self._resolve_host(host, port, traces=traces)
  File "c:\Users\Hong\workspace\maplestorage\maplestorage_backend\.venv\lib\site-packages\aiohttp\connector.py", line 970, in _resolve_host
    await future
  File "c:\Users\Hong\workspace\maplestorage\maplestorage_backend\.venv\lib\site-packages\aiohttp\connector.py", line 1026, in _resolve_host_with_throttle
    addrs = await self._resolver.resolve(host, port, family=self._family)
  File "c:\Users\Hong\workspace\maplestorage\maplestorage_backend\.venv\lib\site-packages\aiohttp\resolver.py", line 39, in resolve
    infos = await self._loop.getaddrinfo(
  File "C:\Users\Hong\AppData\Local\Programs\Python\Python310\lib\asyncio\base_events.py", line 860, in getaddrinfo
    return await self.run_in_executor(
  File "C:\Users\Hong\AppData\Local\Programs\Python\Python310\lib\asyncio\base_events.py", line 818, in run_in_executor
    executor.submit(func, *args), loop=self)
  File "C:\Users\Hong\AppData\Local\Programs\Python\Python310\lib\concurrent\futures\thread.py", line 169, in submit
    raise RuntimeError('cannot schedule new futures after '
RuntimeError: cannot schedule new futures after interpreter shutdown

ERROR 2025-04-07 01:44:55,434 views API 호출/처리 중 예외 발생 (https://open.api.nexon.com/maplestory/v1/character/set-effect): cannot schedule new futures after interpreter shutdown
ERROR 2025-04-07 01:44:55,436 views Traceback (most recent call last):
  File "C:\Users\Hong\workspace\maplestorage\maplestorage_backend\characters\views.py", line 697, in fetch_with_semaphore
    async with session.get(url, params=params, headers=headers) as response:
  File "c:\Users\Hong\workspace\maplestorage\maplestorage_backend\.venv\lib\site-packages\aiohttp\client.py", line 1425, in __aenter__
    self._resp: _RetType = await self._coro
  File "c:\Users\Hong\workspace\maplestorage\maplestorage_backend\.venv\lib\site-packages\aiohttp\client.py", line 703, in _request
    conn = await self._connector.connect(
  File "c:\Users\Hong\workspace\maplestorage\maplestorage_backend\.venv\lib\site-packages\aiohttp\connector.py", line 548, in connect
    proto = await self._create_connection(req, traces, timeout)
  File "c:\Users\Hong\workspace\maplestorage\maplestorage_backend\.venv\lib\site-packages\aiohttp\connector.py", line 1056, in _create_connection
    _, proto = await self._create_direct_connection(req, traces, timeout)
  File "c:\Users\Hong\workspace\maplestorage\maplestorage_backend\.venv\lib\site-packages\aiohttp\connector.py", line 1351, in _create_direct_connection
    hosts = await self._resolve_host(host, port, traces=traces)
  File "c:\Users\Hong\workspace\maplestorage\maplestorage_backend\.venv\lib\site-packages\aiohttp\connector.py", line 970, in _resolve_host
    await future
  File "c:\Users\Hong\workspace\maplestorage\maplestorage_backend\.venv\lib\site-packages\aiohttp\connector.py", line 1026, in _resolve_host_with_throttle
    addrs = await self._resolver.resolve(host, port, family=self._family)
  File "c:\Users\Hong\workspace\maplestorage\maplestorage_backend\.venv\lib\site-packages\aiohttp\resolver.py", line 39, in resolve
    infos = await self._loop.getaddrinfo(
  File "C:\Users\Hong\AppData\Local\Programs\Python\Python310\lib\asyncio\base_events.py", line 860, in getaddrinfo
    return await self.run_in_executor(
  File "C:\Users\Hong\AppData\Local\Programs\Python\Python310\lib\asyncio\base_events.py", line 818, in run_in_executor
    executor.submit(func, *args), loop=self)
  File "C:\Users\Hong\AppData\Local\Programs\Python\Python310\lib\concurrent\futures\thread.py", line 169, in submit
    raise RuntimeError('cannot schedule new futures after '
RuntimeError: cannot schedule new futures after interpreter shutdown

ERROR 2025-04-07 01:44:55,438 views API 호출/처리 중 예외 발생 (https://open.api.nexon.com/maplestory/v1/character/propensity): cannot schedule new futures after interpreter shutdown
ERROR 2025-04-07 01:44:55,439 views Traceback (most recent call last):
  File "C:\Users\Hong\workspace\maplestorage\maplestorage_backend\characters\views.py", line 697, in fetch_with_semaphore
    async with session.get(url, params=params, headers=headers) as response:
  File "c:\Users\Hong\workspace\maplestorage\maplestorage_backend\.venv\lib\site-packages\aiohttp\client.py", line 1425, in __aenter__
    self._resp: _RetType = await self._coro
  File "c:\Users\Hong\workspace\maplestorage\maplestorage_backend\.venv\lib\site-packages\aiohttp\client.py", line 703, in _request
    conn = await self._connector.connect(
  File "c:\Users\Hong\workspace\maplestorage\maplestorage_backend\.venv\lib\site-packages\aiohttp\connector.py", line 548, in connect
    proto = await self._create_connection(req, traces, timeout)
  File "c:\Users\Hong\workspace\maplestorage\maplestorage_backend\.venv\lib\site-packages\aiohttp\connector.py", line 1056, in _create_connection
    _, proto = await self._create_direct_connection(req, traces, timeout)
  File "c:\Users\Hong\workspace\maplestorage\maplestorage_backend\.venv\lib\site-packages\aiohttp\connector.py", line 1351, in _create_direct_connection
    hosts = await self._resolve_host(host, port, traces=traces)
  File "c:\Users\Hong\workspace\maplestorage\maplestorage_backend\.venv\lib\site-packages\aiohttp\connector.py", line 970, in _resolve_host
    await future
  File "c:\Users\Hong\workspace\maplestorage\maplestorage_backend\.venv\lib\site-packages\aiohttp\connector.py", line 1026, in _resolve_host_with_throttle
    addrs = await self._resolver.resolve(host, port, family=self._family)
  File "c:\Users\Hong\workspace\maplestorage\maplestorage_backend\.venv\lib\site-packages\aiohttp\resolver.py", line 39, in resolve
    infos = await self._loop.getaddrinfo(
  File "C:\Users\Hong\AppData\Local\Programs\Python\Python310\lib\asyncio\base_events.py", line 860, in getaddrinfo
    return await self.run_in_executor(
  File "C:\Users\Hong\AppData\Local\Programs\Python\Python310\lib\asyncio\base_events.py", line 818, in run_in_executor
    executor.submit(func, *args), loop=self)
  File "C:\Users\Hong\AppData\Local\Programs\Python\Python310\lib\concurrent\futures\thread.py", line 169, in submit
    raise RuntimeError('cannot schedule new futures after '
RuntimeError: cannot schedule new futures after interpreter shutdown

ERROR 2025-04-07 01:44:55,441 views API 호출/처리 중 예외 발생 (https://open.api.nexon.com/maplestory/v1/character/item-equipment): cannot schedule new futures after interpreter shutdown
ERROR 2025-04-07 01:44:55,443 views Traceback (most recent call last):
  File "C:\Users\Hong\workspace\maplestorage\maplestorage_backend\characters\views.py", line 697, in fetch_with_semaphore
    async with session.get(url, params=params, headers=headers) as response:
  File "c:\Users\Hong\workspace\maplestorage\maplestorage_backend\.venv\lib\site-packages\aiohttp\client.py", line 1425, in __aenter__
    self._resp: _RetType = await self._coro
  File "c:\Users\Hong\workspace\maplestorage\maplestorage_backend\.venv\lib\site-packages\aiohttp\client.py", line 703, in _request
    conn = await self._connector.connect(
  File "c:\Users\Hong\workspace\maplestorage\maplestorage_backend\.venv\lib\site-packages\aiohttp\connector.py", line 548, in connect
    proto = await self._create_connection(req, traces, timeout)
  File "c:\Users\Hong\workspace\maplestorage\maplestorage_backend\.venv\lib\site-packages\aiohttp\connector.py", line 1056, in _create_connection
    _, proto = await self._create_direct_connection(req, traces, timeout)
  File "c:\Users\Hong\workspace\maplestorage\maplestorage_backend\.venv\lib\site-packages\aiohttp\connector.py", line 1351, in _create_direct_connection
    hosts = await self._resolve_host(host, port, traces=traces)
  File "c:\Users\Hong\workspace\maplestorage\maplestorage_backend\.venv\lib\site-packages\aiohttp\connector.py", line 970, in _resolve_host
    await future
  File "c:\Users\Hong\workspace\maplestorage\maplestorage_backend\.venv\lib\site-packages\aiohttp\connector.py", line 1026, in _resolve_host_with_throttle
    addrs = await self._resolver.resolve(host, port, family=self._family)
  File "c:\Users\Hong\workspace\maplestorage\maplestorage_backend\.venv\lib\site-packages\aiohttp\resolver.py", line 39, in resolve
    infos = await self._loop.getaddrinfo(
  File "C:\Users\Hong\AppData\Local\Programs\Python\Python310\lib\asyncio\base_events.py", line 860, in getaddrinfo
    return await self.run_in_executor(
  File "C:\Users\Hong\AppData\Local\Programs\Python\Python310\lib\asyncio\base_events.py", line 818, in run_in_executor
    executor.submit(func, *args), loop=self)
  File "C:\Users\Hong\AppData\Local\Programs\Python\Python310\lib\concurrent\futures\thread.py", line 169, in submit
    raise RuntimeError('cannot schedule new futures after '
RuntimeError: cannot schedule new futures after interpreter shutdown

ERROR 2025-04-07 01:44:55,445 views API 호출/처리 중 예외 발생 (https://open.api.nexon.com/maplestory/v1/character/skill): cannot schedule new futures after interpreter shutdown
ERROR 2025-04-07 01:44:55,447 views Traceback (most recent call last):
  File "C:\Users\Hong\workspace\maplestorage\maplestorage_backend\characters\views.py", line 697, in fetch_with_semaphore
    async with session.get(url, params=params, headers=headers) as response:
  File "c:\Users\Hong\workspace\maplestorage\maplestorage_backend\.venv\lib\site-packages\aiohttp\client.py", line 1425, in __aenter__
    self._resp: _RetType = await self._coro
  File "c:\Users\Hong\workspace\maplestorage\maplestorage_backend\.venv\lib\site-packages\aiohttp\client.py", line 703, in _request
    conn = await self._connector.connect(
  File "c:\Users\Hong\workspace\maplestorage\maplestorage_backend\.venv\lib\site-packages\aiohttp\connector.py", line 548, in connect
    proto = await self._create_connection(req, traces, timeout)
  File "c:\Users\Hong\workspace\maplestorage\maplestorage_backend\.venv\lib\site-packages\aiohttp\connector.py", line 1056, in _create_connection
    _, proto = await self._create_direct_connection(req, traces, timeout)
  File "c:\Users\Hong\workspace\maplestorage\maplestorage_backend\.venv\lib\site-packages\aiohttp\connector.py", line 1351, in _create_direct_connection
    hosts = await self._resolve_host(host, port, traces=traces)
  File "c:\Users\Hong\workspace\maplestorage\maplestorage_backend\.venv\lib\site-packages\aiohttp\connector.py", line 970, in _resolve_host
    await future
  File "c:\Users\Hong\workspace\maplestorage\maplestorage_backend\.venv\lib\site-packages\aiohttp\connector.py", line 1026, in _resolve_host_with_throttle
    addrs = await self._resolver.resolve(host, port, family=self._family)
  File "c:\Users\Hong\workspace\maplestorage\maplestorage_backend\.venv\lib\site-packages\aiohttp\resolver.py", line 39, in resolve
    infos = await self._loop.getaddrinfo(
  File "C:\Users\Hong\AppData\Local\Programs\Python\Python310\lib\asyncio\base_events.py", line 860, in getaddrinfo
    return await self.run_in_executor(
  File "C:\Users\Hong\AppData\Local\Programs\Python\Python310\lib\asyncio\base_events.py", line 818, in run_in_executor
    executor.submit(func, *args), loop=self)
  File "C:\Users\Hong\AppData\Local\Programs\Python\Python310\lib\concurrent\futures\thread.py", line 169, in submit
    raise RuntimeError('cannot schedule new futures after '
RuntimeError: cannot schedule new futures after interpreter shutdown

ERROR 2025-04-07 01:44:55,448 views API 호출/처리 중 예외 발생 (https://open.api.nexon.com/maplestory/v1/character/hexamatrix-stat): cannot schedule new futures after interpreter shutdown
ERROR 2025-04-07 01:44:55,450 views Traceback (most recent call last):
  File "C:\Users\Hong\workspace\maplestorage\maplestorage_backend\characters\views.py", line 697, in fetch_with_semaphore
    async with session.get(url, params=params, headers=headers) as response:
  File "c:\Users\Hong\workspace\maplestorage\maplestorage_backend\.venv\lib\site-packages\aiohttp\client.py", line 1425, in __aenter__
    self._resp: _RetType = await self._coro
  File "c:\Users\Hong\workspace\maplestorage\maplestorage_backend\.venv\lib\site-packages\aiohttp\client.py", line 703, in _request
    conn = await self._connector.connect(
  File "c:\Users\Hong\workspace\maplestorage\maplestorage_backend\.venv\lib\site-packages\aiohttp\connector.py", line 548, in connect
    proto = await self._create_connection(req, traces, timeout)
  File "c:\Users\Hong\workspace\maplestorage\maplestorage_backend\.venv\lib\site-packages\aiohttp\connector.py", line 1056, in _create_connection
    _, proto = await self._create_direct_connection(req, traces, timeout)
  File "c:\Users\Hong\workspace\maplestorage\maplestorage_backend\.venv\lib\site-packages\aiohttp\connector.py", line 1351, in _create_direct_connection
    hosts = await self._resolve_host(host, port, traces=traces)
  File "c:\Users\Hong\workspace\maplestorage\maplestorage_backend\.venv\lib\site-packages\aiohttp\connector.py", line 970, in _resolve_host
    await future
  File "c:\Users\Hong\workspace\maplestorage\maplestorage_backend\.venv\lib\site-packages\aiohttp\connector.py", line 1026, in _resolve_host_with_throttle
    addrs = await self._resolver.resolve(host, port, family=self._family)
  File "c:\Users\Hong\workspace\maplestorage\maplestorage_backend\.venv\lib\site-packages\aiohttp\resolver.py", line 39, in resolve
    infos = await self._loop.getaddrinfo(
  File "C:\Users\Hong\AppData\Local\Programs\Python\Python310\lib\asyncio\base_events.py", line 860, in getaddrinfo
    return await self.run_in_executor(
  File "C:\Users\Hong\AppData\Local\Programs\Python\Python310\lib\asyncio\base_events.py", line 818, in run_in_executor
    executor.submit(func, *args), loop=self)
  File "C:\Users\Hong\AppData\Local\Programs\Python\Python310\lib\concurrent\futures\thread.py", line 169, in submit
    raise RuntimeError('cannot schedule new futures after '
RuntimeError: cannot schedule new futures after interpreter shutdown

ERROR 2025-04-07 01:44:55,451 views API 호출/처리 중 예외 발생 (https://open.api.nexon.com/maplestory/v1/character/beauty-equipment): cannot schedule new futures after interpreter shutdown
ERROR 2025-04-07 01:44:55,453 views Traceback (most recent call last):
  File "C:\Users\Hong\workspace\maplestorage\maplestorage_backend\characters\views.py", line 697, in fetch_with_semaphore
    async with session.get(url, params=params, headers=headers) as response:
  File "c:\Users\Hong\workspace\maplestorage\maplestorage_backend\.venv\lib\site-packages\aiohttp\client.py", line 1425, in __aenter__
    self._resp: _RetType = await self._coro
  File "c:\Users\Hong\workspace\maplestorage\maplestorage_backend\.venv\lib\site-packages\aiohttp\client.py", line 703, in _request
    conn = await self._connector.connect(
  File "c:\Users\Hong\workspace\maplestorage\maplestorage_backend\.venv\lib\site-packages\aiohttp\connector.py", line 548, in connect
    proto = await self._create_connection(req, traces, timeout)
  File "c:\Users\Hong\workspace\maplestorage\maplestorage_backend\.venv\lib\site-packages\aiohttp\connector.py", line 1056, in _create_connection
    _, proto = await self._create_direct_connection(req, traces, timeout)
  File "c:\Users\Hong\workspace\maplestorage\maplestorage_backend\.venv\lib\site-packages\aiohttp\connector.py", line 1351, in _create_direct_connection
    hosts = await self._resolve_host(host, port, traces=traces)
  File "c:\Users\Hong\workspace\maplestorage\maplestorage_backend\.venv\lib\site-packages\aiohttp\connector.py", line 970, in _resolve_host
    await future
  File "c:\Users\Hong\workspace\maplestorage\maplestorage_backend\.venv\lib\site-packages\aiohttp\connector.py", line 1026, in _resolve_host_with_throttle
    addrs = await self._resolver.resolve(host, port, family=self._family)
  File "c:\Users\Hong\workspace\maplestorage\maplestorage_backend\.venv\lib\site-packages\aiohttp\resolver.py", line 39, in resolve
    infos = await self._loop.getaddrinfo(
  File "C:\Users\Hong\AppData\Local\Programs\Python\Python310\lib\asyncio\base_events.py", line 860, in getaddrinfo
    return await self.run_in_executor(
  File "C:\Users\Hong\AppData\Local\Programs\Python\Python310\lib\asyncio\base_events.py", line 818, in run_in_executor
    executor.submit(func, *args), loop=self)
  File "C:\Users\Hong\AppData\Local\Programs\Python\Python310\lib\concurrent\futures\thread.py", line 169, in submit
    raise RuntimeError('cannot schedule new futures after '
RuntimeError: cannot schedule new futures after interpreter shutdown

ERROR 2025-04-07 01:44:55,455 views API 호출/처리 중 예외 발생 (https://open.api.nexon.com/maplestory/v1/character/popularity): cannot schedule new futures after interpreter shutdown
ERROR 2025-04-07 01:44:55,457 views Traceback (most recent call last):
  File "C:\Users\Hong\workspace\maplestorage\maplestorage_backend\characters\views.py", line 697, in fetch_with_semaphore
    async with session.get(url, params=params, headers=headers) as response:
  File "c:\Users\Hong\workspace\maplestorage\maplestorage_backend\.venv\lib\site-packages\aiohttp\client.py", line 1425, in __aenter__
    self._resp: _RetType = await self._coro
  File "c:\Users\Hong\workspace\maplestorage\maplestorage_backend\.venv\lib\site-packages\aiohttp\client.py", line 703, in _request
    conn = await self._connector.connect(
  File "c:\Users\Hong\workspace\maplestorage\maplestorage_backend\.venv\lib\site-packages\aiohttp\connector.py", line 548, in connect
    proto = await self._create_connection(req, traces, timeout)
  File "c:\Users\Hong\workspace\maplestorage\maplestorage_backend\.venv\lib\site-packages\aiohttp\connector.py", line 1056, in _create_connection
    _, proto = await self._create_direct_connection(req, traces, timeout)
  File "c:\Users\Hong\workspace\maplestorage\maplestorage_backend\.venv\lib\site-packages\aiohttp\connector.py", line 1351, in _create_direct_connection
    hosts = await self._resolve_host(host, port, traces=traces)
  File "c:\Users\Hong\workspace\maplestorage\maplestorage_backend\.venv\lib\site-packages\aiohttp\connector.py", line 970, in _resolve_host
    await future
  File "c:\Users\Hong\workspace\maplestorage\maplestorage_backend\.venv\lib\site-packages\aiohttp\connector.py", line 1026, in _resolve_host_with_throttle
    addrs = await self._resolver.resolve(host, port, family=self._family)
  File "c:\Users\Hong\workspace\maplestorage\maplestorage_backend\.venv\lib\site-packages\aiohttp\resolver.py", line 39, in resolve
    infos = await self._loop.getaddrinfo(
  File "C:\Users\Hong\AppData\Local\Programs\Python\Python310\lib\asyncio\base_events.py", line 860, in getaddrinfo
    return await self.run_in_executor(
  File "C:\Users\Hong\AppData\Local\Programs\Python\Python310\lib\asyncio\base_events.py", line 818, in run_in_executor
    executor.submit(func, *args), loop=self)
  File "C:\Users\Hong\AppData\Local\Programs\Python\Python310\lib\concurrent\futures\thread.py", line 169, in submit
    raise RuntimeError('cannot schedule new futures after '
RuntimeError: cannot schedule new futures after interpreter shutdown

ERROR 2025-04-07 01:44:55,459 views API 호출/처리 중 예외 발생 (https://open.api.nexon.com/maplestory/v1/character/cashitem-equipment): cannot schedule new futures after interpreter shutdown
ERROR 2025-04-07 01:44:55,460 views Traceback (most recent call last):
  File "C:\Users\Hong\workspace\maplestorage\maplestorage_backend\characters\views.py", line 697, in fetch_with_semaphore
    async with session.get(url, params=params, headers=headers) as response:
  File "c:\Users\Hong\workspace\maplestorage\maplestorage_backend\.venv\lib\site-packages\aiohttp\client.py", line 1425, in __aenter__
    self._resp: _RetType = await self._coro
  File "c:\Users\Hong\workspace\maplestorage\maplestorage_backend\.venv\lib\site-packages\aiohttp\client.py", line 703, in _request
    conn = await self._connector.connect(
  File "c:\Users\Hong\workspace\maplestorage\maplestorage_backend\.venv\lib\site-packages\aiohttp\connector.py", line 548, in connect
    proto = await self._create_connection(req, traces, timeout)
  File "c:\Users\Hong\workspace\maplestorage\maplestorage_backend\.venv\lib\site-packages\aiohttp\connector.py", line 1056, in _create_connection
    _, proto = await self._create_direct_connection(req, traces, timeout)
  File "c:\Users\Hong\workspace\maplestorage\maplestorage_backend\.venv\lib\site-packages\aiohttp\connector.py", line 1351, in _create_direct_connection
    hosts = await self._resolve_host(host, port, traces=traces)
  File "c:\Users\Hong\workspace\maplestorage\maplestorage_backend\.venv\lib\site-packages\aiohttp\connector.py", line 970, in _resolve_host
    await future
  File "c:\Users\Hong\workspace\maplestorage\maplestorage_backend\.venv\lib\site-packages\aiohttp\connector.py", line 1026, in _resolve_host_with_throttle
    addrs = await self._resolver.resolve(host, port, family=self._family)
  File "c:\Users\Hong\workspace\maplestorage\maplestorage_backend\.venv\lib\site-packages\aiohttp\resolver.py", line 39, in resolve
    infos = await self._loop.getaddrinfo(
  File "C:\Users\Hong\AppData\Local\Programs\Python\Python310\lib\asyncio\base_events.py", line 860, in getaddrinfo
    return await self.run_in_executor(
  File "C:\Users\Hong\AppData\Local\Programs\Python\Python310\lib\asyncio\base_events.py", line 818, in run_in_executor
    executor.submit(func, *args), loop=self)
  File "C:\Users\Hong\AppData\Local\Programs\Python\Python310\lib\concurrent\futures\thread.py", line 169, in submit
    raise RuntimeError('cannot schedule new futures after '
RuntimeError: cannot schedule new futures after interpreter shutdown

ERROR 2025-04-07 01:44:55,462 views API 호출/처리 중 예외 발생 (https://open.api.nexon.com/maplestory/v1/character/basic): cannot schedule new futures after interpreter shutdown
ERROR 2025-04-07 01:44:55,466 views Traceback (most recent call last):
  File "C:\Users\Hong\workspace\maplestorage\maplestorage_backend\characters\views.py", line 697, in fetch_with_semaphore
    async with session.get(url, params=params, headers=headers) as response:
  File "c:\Users\Hong\workspace\maplestorage\maplestorage_backend\.venv\lib\site-packages\aiohttp\client.py", line 1425, in __aenter__
    self._resp: _RetType = await self._coro
  File "c:\Users\Hong\workspace\maplestorage\maplestorage_backend\.venv\lib\site-packages\aiohttp\client.py", line 703, in _request
    conn = await self._connector.connect(
  File "c:\Users\Hong\workspace\maplestorage\maplestorage_backend\.venv\lib\site-packages\aiohttp\connector.py", line 548, in connect
    proto = await self._create_connection(req, traces, timeout)
  File "c:\Users\Hong\workspace\maplestorage\maplestorage_backend\.venv\lib\site-packages\aiohttp\connector.py", line 1056, in _create_connection
    _, proto = await self._create_direct_connection(req, traces, timeout)
  File "c:\Users\Hong\workspace\maplestorage\maplestorage_backend\.venv\lib\site-packages\aiohttp\connector.py", line 1351, in _create_direct_connection
    hosts = await self._resolve_host(host, port, traces=traces)
  File "c:\Users\Hong\workspace\maplestorage\maplestorage_backend\.venv\lib\site-packages\aiohttp\connector.py", line 995, in _resolve_host
    return await asyncio.shield(resolved_host_task)
  File "C:\Users\Hong\workspace\maplestorage\maplestorage_backend\characters\views.py", line 697, in fetch_with_semaphore
    async with session.get(url, params=params, headers=headers) as response:
  File "c:\Users\Hong\workspace\maplestorage\maplestorage_backend\.venv\lib\site-packages\aiohttp\client.py", line 1425, in __aenter__
    self._resp: _RetType = await self._coro
  File "c:\Users\Hong\workspace\maplestorage\maplestorage_backend\.venv\lib\site-packages\aiohttp\client.py", line 703, in _request
    conn = await self._connector.connect(
  File "c:\Users\Hong\workspace\maplestorage\maplestorage_backend\.venv\lib\site-packages\aiohttp\connector.py", line 548, in connect
    proto = await self._create_connection(req, traces, timeout)
  File "c:\Users\Hong\workspace\maplestorage\maplestorage_backend\.venv\lib\site-packages\aiohttp\connector.py", line 1056, in _create_connection
    _, proto = await self._create_direct_connection(req, traces, timeout)
  File "c:\Users\Hong\workspace\maplestorage\maplestorage_backend\.venv\lib\site-packages\aiohttp\connector.py", line 1351, in _create_direct_connection
    hosts = await self._resolve_host(host, port, traces=traces)
  File "c:\Users\Hong\workspace\maplestorage\maplestorage_backend\.venv\lib\site-packages\aiohttp\connector.py", line 970, in _resolve_host
    await future
  File "c:\Users\Hong\workspace\maplestorage\maplestorage_backend\.venv\lib\site-packages\aiohttp\connector.py", line 1026, in _resolve_host_with_throttle
    addrs = await self._resolver.resolve(host, port, family=self._family)
  File "c:\Users\Hong\workspace\maplestorage\maplestorage_backend\.venv\lib\site-packages\aiohttp\resolver.py", line 39, in resolve
    infos = await self._loop.getaddrinfo(
  File "C:\Users\Hong\AppData\Local\Programs\Python\Python310\lib\asyncio\base_events.py", line 860, in getaddrinfo
    return await self.run_in_executor(
  File "C:\Users\Hong\AppData\Local\Programs\Python\Python310\lib\asyncio\base_events.py", line 818, in run_in_executor
    executor.submit(func, *args), loop=self)
  File "C:\Users\Hong\AppData\Local\Programs\Python\Python310\lib\concurrent\futures\thread.py", line 169, in submit
    raise RuntimeError('cannot schedule new futures after '
RuntimeError: cannot schedule new futures after interpreter shutdown

ERROR 2025-04-07 01:44:55,467 views API 호출/처리 중 예외 발생 (https://open.api.nexon.com/maplestory/v1/character/hyper-stat): cannot schedule new futures after interpreter shutdown
ERROR 2025-04-07 01:44:55,471 views Traceback (most recent call last):
  File "C:\Users\Hong\workspace\maplestorage\maplestorage_backend\characters\views.py", line 697, in fetch_with_semaphore
    async with session.get(url, params=params, headers=headers) as response:
  File "c:\Users\Hong\workspace\maplestorage\maplestorage_backend\.venv\lib\site-packages\aiohttp\client.py", line 1425, in __aenter__
    self._resp: _RetType = await self._coro
  File "c:\Users\Hong\workspace\maplestorage\maplestorage_backend\.venv\lib\site-packages\aiohttp\client.py", line 703, in _request
    conn = await self._connector.connect(
  File "c:\Users\Hong\workspace\maplestorage\maplestorage_backend\.venv\lib\site-packages\aiohttp\connector.py", line 548, in connect
    proto = await self._create_connection(req, traces, timeout)
  File "c:\Users\Hong\workspace\maplestorage\maplestorage_backend\.venv\lib\site-packages\aiohttp\connector.py", line 1056, in _create_connection
    _, proto = await self._create_direct_connection(req, traces, timeout)
  File "c:\Users\Hong\workspace\maplestorage\maplestorage_backend\.venv\lib\site-packages\aiohttp\connector.py", line 1351, in _create_direct_connection
    hosts = await self._resolve_host(host, port, traces=traces)
  File "c:\Users\Hong\workspace\maplestorage\maplestorage_backend\.venv\lib\site-packages\aiohttp\connector.py", line 995, in _resolve_host
    return await asyncio.shield(resolved_host_task)
  File "c:\Users\Hong\workspace\maplestorage\maplestorage_backend\.venv\lib\site-packages\aiohttp\connector.py", line 1026, in _resolve_host_with_throttle
    addrs = await self._resolver.resolve(host, port, family=self._family)
  File "c:\Users\Hong\workspace\maplestorage\maplestorage_backend\.venv\lib\site-packages\aiohttp\resolver.py", line 39, in resolve
    infos = await self._loop.getaddrinfo(
  File "C:\Users\Hong\AppData\Local\Programs\Python\Python310\lib\asyncio\base_events.py", line 860, in getaddrinfo
    return await self.run_in_executor(
  File "C:\Users\Hong\AppData\Local\Programs\Python\Python310\lib\asyncio\base_events.py", line 818, in run_in_executor
    executor.submit(func, *args), loop=self)
  File "C:\Users\Hong\AppData\Local\Programs\Python\Python310\lib\concurrent\futures\thread.py", line 169, in submit
    raise RuntimeError('cannot schedule new futures after '
RuntimeError: cannot schedule new futures after interpreter shutdown

ERROR 2025-04-07 01:45:12,965 views 데이터베이스 저장 중 오류 발생: 인기도 정보 생성 중 오류 발생: 'NoneType' object has no attribute 'astimezone'
ERROR 2025-04-07 01:45:13,184 views 데이터베이스 저장 중 오류 발생: V매트릭스 정보 생성 중 오류 발생: 'NoneType' object has no attribute 'astimezone'
ERROR 2025-04-07 01:45:19,789 views 데이터베이스 저장 중 오류 발생: 장비 정보 생성 중 오류 발생: 'NoneType' object has no attribute 'astimezone'
ERROR 2025-04-07 01:53:39,929 views CharacterBasic 데이터 검증 실패: 1 validation error for CharacterBasicSchema
character_guild_name
  Input should be a valid string [type=string_type, input_value=None, input_type=NoneType]
    For further information visit https://errors.pydantic.dev/2.10/v/string_type
ERROR 2025-04-07 01:53:39,930 views 데이터베이스 저장 중 오류 발생: CharacterBasic 데이터 검증 실패: 1 validation error for CharacterBasicSchema
character_guild_name
  Input should be a valid string [type=string_type, input_value=None, input_type=NoneType]
    For further information visit https://errors.pydantic.dev/2.10/v/string_type
ERROR 2025-04-07 01:55:22,217 views CharacterBasic 데이터 검증 실패: 1 validation error for CharacterBasicSchema
character_guild_name
  Input should be a valid string [type=string_type, input_value=None, input_type=NoneType]
    For further information visit https://errors.pydantic.dev/2.10/v/string_type
ERROR 2025-04-07 01:55:22,218 views 데이터베이스 저장 중 오류 발생: CharacterBasic 데이터 검증 실패: 1 validation error for CharacterBasicSchema
character_guild_name
  Input should be a valid string [type=string_type, input_value=None, input_type=NoneType]
    For further information visit https://errors.pydantic.dev/2.10/v/string_type
ERROR 2025-04-07 01:59:03,653 views 데이터베이스 저장 중 오류 발생: 장비 정보 생성 중 오류 발생: ['“expired” value has an invalid format. It must be in YYYY-MM-DD HH:MM[:ss[.uuuuuu]][TZ] format.']
ERROR 2025-04-07 02:04:44,202 views 데이터베이스 저장 중 오류 발생: 장비 정보 생성 중 오류 발생: ['“expired” value has an invalid format. It must be in YYYY-MM-DD HH:MM[:ss[.uuuuuu]][TZ] format.']
ERROR 2025-04-07 02:04:45,932 views 데이터베이스 저장 중 오류 발생: 장비 정보 생성 중 오류 발생: ['“expired” value has an invalid format. It must be in YYYY-MM-DD HH:MM[:ss[.uuuuuu]][TZ] format.']
ERROR 2025-04-07 02:05:05,724 views 데이터베이스 저장 중 오류 발생: 장비 정보 생성 중 오류 발생: ['“expired” value has an invalid format. It must be in YYYY-MM-DD HH:MM[:ss[.uuuuuu]][TZ] format.']
ERROR 2025-04-07 02:06:52,371 views 데이터베이스 저장 중 오류 발생: 장비 정보 생성 중 오류 발생: module 'django.utils.timezone' has no attribute 'utc'
ERROR 2025-04-07 02:08:08,459 views 데이터베이스 저장 중 오류 발생: 장비 정보 생성 중 오류 발생: ['“expired” value has an invalid format. It must be in YYYY-MM-DD HH:MM[:ss[.uuuuuu]][TZ] format.']
ERROR 2025-04-07 02:09:20,863 views 데이터베이스 저장 중 오류 발생: 장비 정보 생성 중 오류 발생: ['“expired” value has an invalid format. It must be in YYYY-MM-DD HH:MM[:ss[.uuuuuu]][TZ] format.']
ERROR 2025-04-07 02:10:16,057 models Title 생성 중 오류 발생: ['“expired” value has an invalid format. It must be in YYYY-MM-DD HH:MM[:ss[.uuuuuu]][TZ] format.']
ERROR 2025-04-07 02:10:16,064 views 데이터베이스 저장 중 오류 발생: 장비 정보 생성 중 오류 발생: module 'django.utils.timezone' has no attribute 'utc'
ERROR 2025-04-07 02:13:43,457 views 데이터베이스 저장 중 오류 발생: 장비 정보 생성 중 오류 발생: module 'django.utils.timezone' has no attribute 'utc'
ERROR 2025-04-07 02:14:12,222 models Title 생성 중 오류 발생: module 'datetime' has no attribute 'strptime'
ERROR 2025-04-07 02:14:27,794 views 데이터베이스 저장 중 오류 발생: 장비 정보 생성 중 오류 발생: module 'django.utils.timezone' has no attribute 'utc'
ERROR 2025-04-07 02:14:35,362 views 데이터베이스 저장 중 오류 발생: 장비 정보 생성 중 오류 발생: module 'django.utils.timezone' has no attribute 'utc'
ERROR 2025-04-07 02:16:41,026 views 데이터베이스 저장 중 오류 발생: 장비 정보 생성 중 오류 발생: ['“expired” value has an invalid format. It must be in YYYY-MM-DD HH:MM[:ss[.uuuuuu]][TZ] format.']
ERROR 2025-04-07 02:16:57,805 views 데이터베이스 저장 중 오류 발생: 장비 정보 생성 중 오류 발생: ['“expired” value has an invalid format. It must be in YYYY-MM-DD HH:MM[:ss[.uuuuuu]][TZ] format.']
ERROR 2025-04-07 02:20:37,494 views CharacterBasic 데이터 검증 실패: 1 validation error for CharacterBasicSchema
character_guild_name
  Input should be a valid string [type=string_type, input_value=None, input_type=NoneType]
    For further information visit https://errors.pydantic.dev/2.10/v/string_type
ERROR 2025-04-07 02:20:37,495 views 데이터베이스 저장 중 오류 발생: CharacterBasic 데이터 검증 실패: 1 validation error for CharacterBasicSchema
character_guild_name
  Input should be a valid string [type=string_type, input_value=None, input_type=NoneType]
    For further information visit https://errors.pydantic.dev/2.10/v/string_type
ERROR 2025-04-07 02:21:39,985 views 전체 데이터 조회 중 오류 발생 - 캐릭터명: 식노밍, OCID: None, 총 소요시간: 0.15초, 오류: 400 Client Error: Bad Request for url: https://open.api.nexon.com/maplestory/v1/character/basic?ocid=87bda73000b0693155f8777b08b64464
ERROR 2025-04-07 02:21:39,989 views Traceback (most recent call last):
  File "C:\Users\Hong\workspace\maplestorage\maplestorage_backend\characters\views.py", line 561, in get
    ocid_data = CharacterIdView()._fetch_and_process_data(request)
  File "C:\Users\Hong\workspace\maplestorage\maplestorage_backend\characters\views.py", line 221, in _fetch_and_process_data
    basic_data = self.get_api_data(
  File "C:\Users\Hong\workspace\maplestorage\maplestorage_backend\util\rate_limiter.py", line 49, in wrapper
    return func(*args, **kwargs)
  File "C:\Users\Hong\workspace\maplestorage\maplestorage_backend\characters\mixins.py", line 51, in get_api_data
    response.raise_for_status()
  File "c:\Users\Hong\workspace\maplestorage\maplestorage_backend\.venv\lib\site-packages\requests\models.py", line 1024, in raise_for_status
    raise HTTPError(http_error_msg, response=self)
requests.exceptions.HTTPError: 400 Client Error: Bad Request for url: https://open.api.nexon.com/maplestory/v1/character/basic?ocid=87bda73000b0693155f8777b08b64464

ERROR 2025-04-07 02:21:39,991 log Internal Server Error: /characters/all/
ERROR 2025-04-07 02:21:46,829 views 전체 데이터 조회 중 오류 발생 - 캐릭터명: 싱노밍, OCID: None, 총 소요시간: 0.13초, 오류: 400 Client Error: Bad Request for url: https://open.api.nexon.com/maplestory/v1/character/basic?ocid=b8a87f11376004afa862716963bc2bd3
ERROR 2025-04-07 02:21:46,830 views Traceback (most recent call last):
  File "C:\Users\Hong\workspace\maplestorage\maplestorage_backend\characters\views.py", line 561, in get
    ocid_data = CharacterIdView()._fetch_and_process_data(request)
  File "C:\Users\Hong\workspace\maplestorage\maplestorage_backend\characters\views.py", line 221, in _fetch_and_process_data
    basic_data = self.get_api_data(
  File "C:\Users\Hong\workspace\maplestorage\maplestorage_backend\util\rate_limiter.py", line 49, in wrapper
    return func(*args, **kwargs)
  File "C:\Users\Hong\workspace\maplestorage\maplestorage_backend\characters\mixins.py", line 51, in get_api_data
    response.raise_for_status()
  File "c:\Users\Hong\workspace\maplestorage\maplestorage_backend\.venv\lib\site-packages\requests\models.py", line 1024, in raise_for_status
    raise HTTPError(http_error_msg, response=self)
requests.exceptions.HTTPError: 400 Client Error: Bad Request for url: https://open.api.nexon.com/maplestory/v1/character/basic?ocid=b8a87f11376004afa862716963bc2bd3

ERROR 2025-04-07 02:21:46,831 log Internal Server Error: /characters/all/
ERROR 2025-04-07 02:25:59,234 views CharacterBasic 데이터 검증 실패: 1 validation error for CharacterBasicSchema
character_guild_name
  Input should be a valid string [type=string_type, input_value=None, input_type=NoneType]
    For further information visit https://errors.pydantic.dev/2.10/v/string_type
ERROR 2025-04-07 02:25:59,234 views 데이터베이스 저장 중 오류 발생: CharacterBasic 데이터 검증 실패: 1 validation error for CharacterBasicSchema
character_guild_name
  Input should be a valid string [type=string_type, input_value=None, input_type=NoneType]
    For further information visit https://errors.pydantic.dev/2.10/v/string_type
